export const catchError = asyncFonc => (req, res, next) => asyncFonc(req, res, next).catch()